<sdf version='1.6'>
  <world name='default'>
    <model name='ground_plane'>
      <static>1</static>
      <link name='link'>
        <collision name='collision'>
          <geometry>
            <plane>
              <normal>0 0 1</normal>
              <size>100 100</size>
            </plane>
          </geometry>
          <surface>
            <friction>
              <ode>
                <mu>100</mu>
                <mu2>50</mu2>
              </ode>
              <torsional>
                <ode/>
              </torsional>
            </friction>
            <contact>
              <ode/>
            </contact>
            <bounce/>
          </surface>
          <max_contacts>10</max_contacts>
        </collision>
        <visual name='visual'>
          <cast_shadows>0</cast_shadows>
          <geometry>
            <plane>
              <normal>0 0 1</normal>
              <size>100 100</size>
            </plane>
          </geometry>
          <material>
            <script>
              <uri>file://media/materials/scripts/gazebo.material</uri>
              <name>Gazebo/Grey</name>
            </script>
          </material>
        </visual>
        <self_collide>0</self_collide>
        <kinematic>0</kinematic>
        <gravity>1</gravity>
      </link>
    </model>
    <light name='sun' type='directional'>
      <cast_shadows>1</cast_shadows>
      <pose frame=''>0 0 10 0 -0 0</pose>
      <diffuse>0.8 0.8 0.8 1</diffuse>
      <specular>0.1 0.1 0.1 1</specular>
      <attenuation>
        <range>1000</range>
        <constant>0.9</constant>
        <linear>0.01</linear>
        <quadratic>0.001</quadratic>
      </attenuation>
      <direction>-0.5 0.5 -1</direction>
    </light>
    <gui fullscreen='0'>
      <camera name='user_camera'>
        <pose frame=''>-46.5575 -26.8384 25.1215 -0 0.331643 0.504191</pose>
        <view_controller>orbit</view_controller>
        <projection_type>perspective</projection_type>
      </camera>
    </gui>
    <gravity>0 0 -9.8</gravity>
    <magnetic_field>6e-06 2.3e-05 -4.2e-05</magnetic_field>
    <atmosphere type='adiabatic'/>
    <physics name='default_physics' default='0' type='ode'>
      <max_step_size>0.001</max_step_size>
      <real_time_factor>1</real_time_factor>
      <real_time_update_rate>1000</real_time_update_rate>
    </physics>
    <scene>
      <ambient>0.4 0.4 0.4 1</ambient>
      <background>0.7 0.7 0.7 1</background>
      <shadows>1</shadows>
    </scene>
    <spherical_coordinates>
      <surface_model>EARTH_WGS84</surface_model>
      <latitude_deg>0</latitude_deg>
      <longitude_deg>0</longitude_deg>
      <elevation>0</elevation>
      <heading_deg>0</heading_deg>
    </spherical_coordinates>
    <model name='cranebot'>
      <link name='link1'>
        <pose frame=''>0 0 0 0 -0 0</pose>
        <inertial>
          <pose frame=''>0 0 0.5 0 -0 0</pose>
          <mass>1</mass>
          <inertia>
            <ixx>1</ixx>
            <ixy>0</ixy>
            <ixz>1</ixz>
            <iyy>0</iyy>
            <iyz>1</iyz>
            <izz>0</izz>
          </inertia>
        </inertial>
        <visual name='link1_visual'>
          <pose frame=''>0 0 0.5 0 -0 0</pose>
          <geometry>
            <box>
              <size>15 3 1</size>
            </box>
          </geometry>
          <material>
            <script>
              <name>Gazebo/Orange</name>
              <uri>file://media/materials/scripts/gazebo.material</uri>
            </script>
          </material>
        </visual>
        <gravity>1</gravity>
        <velocity_decay/>
        <self_collide>0</self_collide>
        <kinematic>0</kinematic>
      </link>
      <joint name='fixed' type='revolute'>
        <child>link1</child>
        <parent>world</parent>
        <axis>
          <limit>
            <lower>0</lower>
            <upper>0</upper>
          </limit>
          <dynamics>
            <damping>0</damping>
            <friction>0</friction>
            <spring_reference>0</spring_reference>
            <spring_stiffness>0</spring_stiffness>
          </dynamics>
          <use_parent_model_frame>1</use_parent_model_frame>
          <xyz>0 0 1</xyz>
        </axis>
      </joint>
      <link name='link2'>
        <pose frame=''>-6 0 1 0 -0 0</pose>
        <inertial>
          <pose frame=''>0 0 0.1 0 -0 0</pose>
          <mass>0.1</mass>
          <inertia>
            <ixx>1</ixx>
            <ixy>0</ixy>
            <ixz>0</ixz>
            <iyy>1</iyy>
            <iyz>0</iyz>
            <izz>1</izz>
          </inertia>
        </inertial>
        <visual name='link2_visual'>
          <pose frame=''>0 0 0.1 0 -0 0</pose>
          <geometry>
            <cylinder>
              <length>0.2</length>
              <radius>0.8</radius>
            </cylinder>
          </geometry>
          <material>
            <script>
              <name>Gazebo/Black</name>
              <uri>file://media/materials/scripts/gazebo.material</uri>
            </script>
          </material>
        </visual>
        <gravity>1</gravity>
        <velocity_decay/>
        <self_collide>0</self_collide>
        <kinematic>0</kinematic>
      </link>
      <joint name='azimuth' type='revolute'>
        <child>link2</child>
        <parent>link1</parent>
        <axis>
          <xyz>0 0 -1</xyz>
          <limit>
            <lower>-3.14</lower>
            <upper>3.14</upper>
            <effort>10000</effort>
            <velocity>0.01</velocity>
          </limit>
          <dynamics>
            <spring_reference>0</spring_reference>
            <spring_stiffness>0</spring_stiffness>
          </dynamics>
          <use_parent_model_frame>1</use_parent_model_frame>
        </axis>
      </joint>
      <link name='prlink1'>
        <pose frame=''>-6 0 1.1 0 -0 0</pose>
        <inertial>
          <pose frame=''>7 0 0 0 -0 0</pose>
          <mass>1</mass>
          <inertia>
            <ixx>1</ixx>
            <ixy>0</ixy>
            <ixz>0</ixz>
            <iyy>1</iyy>
            <iyz>0</iyz>
            <izz>1</izz>
          </inertia>
        </inertial>
        <visual name='prlink1_visual'>
          <pose frame=''>7 0 0 0 -0 0</pose>
          <geometry>
            <box>
              <size>14 0.25 0.5</size>
            </box>
          </geometry>
          <material>
            <script>
              <name>Gazebo/Orange</name>
              <uri>file://media/materials/scripts/gazebo.material</uri>
            </script>
          </material>
        </visual>
        <gravity>1</gravity>
        <velocity_decay/>
        <self_collide>0</self_collide>
        <kinematic>0</kinematic>
      </link>
      <joint name='elevation' type='revolute'>
        <child>prlink1</child>
        <parent>link2</parent>
        <axis>
          <xyz>0 -1 0</xyz>
          <limit>
            <lower>0</lower>
            <upper>1.5</upper>
            <effort>10000</effort>
            <velocity>0.01</velocity>
          </limit>
          <dynamics>
            <spring_reference>0</spring_reference>
            <spring_stiffness>0</spring_stiffness>
          </dynamics>
          <use_parent_model_frame>1</use_parent_model_frame>
        </axis>
      </joint>
      <link name='prlink2'>
        <pose frame=''>-6 0 1.1 0 -0 0</pose>
        <inertial>
          <pose frame=''>7 0 0 0 -0 0</pose>
          <mass>1</mass>
          <inertia>
            <ixx>1</ixx>
            <ixy>0</ixy>
            <ixz>0</ixz>
            <iyy>1</iyy>
            <iyz>0</iyz>
            <izz>1</izz>
          </inertia>
        </inertial>
        <visual name='prlink2_visual'>
          <pose frame=''>7 0 0 0 -0 0</pose>
          <geometry>
            <box>
              <size>14 0.25 0.5</size>
            </box>
          </geometry>
          <material>
            <script>
              <name>Gazebo/Orange</name>
              <uri>file://media/materials/scripts/gazebo.material</uri>
            </script>
          </material>
        </visual>
        <gravity>1</gravity>
        <velocity_decay/>
        <self_collide>0</self_collide>
        <kinematic>0</kinematic>
      </link>
      <joint name='prj1' type='prismatic'>
        <child>prlink2</child>
        <parent>prlink1</parent>
        <axis>
          <xyz>1 0 0</xyz>
          <limit>
            <lower>0</lower>
            <upper>14</upper>
            <effort>10000</effort>
            <velocity>0.05</velocity>
          </limit>
          <dynamics>
            <spring_reference>0</spring_reference>
            <spring_stiffness>0</spring_stiffness>
          </dynamics>
          <use_parent_model_frame>1</use_parent_model_frame>
        </axis>
      </joint>
      <link name='prlink3'>
        <pose frame=''>-6 0 1.1 0 -0 0</pose>
        <inertial>
          <pose frame=''>7 0 0 0 -0 0</pose>
          <mass>1</mass>
          <inertia>
            <ixx>1</ixx>
            <ixy>0</ixy>
            <ixz>0</ixz>
            <iyy>1</iyy>
            <iyz>0</iyz>
            <izz>1</izz>
          </inertia>
        </inertial>
        <visual name='prlink3_visual'>
          <pose frame=''>7 0 0 0 -0 0</pose>
          <geometry>
            <box>
              <size>14 0.25 0.5</size>
            </box>
          </geometry>
          <material>
            <script>
              <name>Gazebo/Orange</name>
              <uri>file://media/materials/scripts/gazebo.material</uri>
            </script>
          </material>
        </visual>
        <gravity>1</gravity>
        <velocity_decay/>
        <self_collide>0</self_collide>
        <kinematic>0</kinematic>
      </link>
      <joint name='prj2' type='prismatic'>
        <child>prlink3</child>
        <parent>prlink2</parent>
        <axis>
          <xyz>1 0 0</xyz>
          <limit>
            <lower>0</lower>
            <upper>14</upper>
            <effort>10000</effort>
            <velocity>0.05</velocity>
          </limit>
          <dynamics>
            <spring_reference>0</spring_reference>
            <spring_stiffness>0</spring_stiffness>
          </dynamics>
          <use_parent_model_frame>1</use_parent_model_frame>
        </axis>
      </joint>
      <link name='link4'>
        <pose frame=''>10.5 0 1.1 0 -0 0</pose>
        <inertial>
          <pose frame=''>0 0 0 0 -0 0</pose>
          <mass>0.001</mass>
          <inertia>
            <ixx>1</ixx>
            <ixy>0</ixy>
            <ixz>0</ixz>
            <iyy>1</iyy>
            <iyz>0</iyz>
            <izz>1</izz>
          </inertia>
        </inertial>
        <gravity>1</gravity>
        <velocity_decay/>
        <self_collide>0</self_collide>
        <kinematic>0</kinematic>
      </link>
      <joint name='free_joint' type='revolute'>
        <child>link4</child>
        <parent>prlink3</parent>
        <axis>
          <xyz>0 1 0</xyz>
          <limit>
            <lower>-1e+16</lower>
            <upper>1e+16</upper>
          </limit>
          <dynamics>
            <damping>10</damping>
            <friction>0</friction>
            <spring_reference>0</spring_reference>
            <spring_stiffness>0</spring_stiffness>
          </dynamics>
          <use_parent_model_frame>1</use_parent_model_frame>
        </axis>
      </joint>
      <link name='load'>
        <pose frame=''>10.5 0 1.1 0 -0 0</pose>
        <inertial>
          <pose frame=''>0 0 0 0 -0 0</pose>
          <mass>0.1</mass>
          <inertia>
            <ixx>1</ixx>
            <ixy>0</ixy>
            <ixz>0</ixz>
            <iyy>1</iyy>
            <iyz>0</iyz>
            <izz>1</izz>
          </inertia>
        </inertial>
        <collision name='load_collision'>
          <pose frame=''>0 0 -1.5 0 -0 0</pose>
          <geometry>
            <box>
              <size>0.01 0.01 0.01</size>
            </box>
          </geometry>
          <surface>
            <contact>
              <ode/>
            </contact>
            <friction>
              <ode/>
              <torsional>
                <ode/>
              </torsional>
            </friction>
            <bounce/>
          </surface>
          <max_contacts>10</max_contacts>
        </collision>
        <visual name='load_visual'>
          <pose frame=''>0 0 0 0 -0 0</pose>
          <geometry>
            <box>
              <size>3 3 3</size>
            </box>
          </geometry>
          <material>
            <script>
              <name>Gazebo/Orange</name>
              <uri>file://media/materials/scripts/gazebo.material</uri>
            </script>
          </material>
        </visual>
        <gravity>1</gravity>
        <velocity_decay/>
        <self_collide>0</self_collide>
        <kinematic>0</kinematic>
      </link>
      <joint name='cablejoint' type='prismatic'>
        <child>load</child>
        <parent>link4</parent>
        <axis>
          <xyz>0 0 1</xyz>
          <limit>
            <lower>-50</lower>
            <upper>0</upper>
            <effort>100</effort>
            <velocity>0.01</velocity>
          </limit>
          <dynamics>
            <damping>0</damping>
            <friction>10</friction>
            <spring_reference>0</spring_reference>
            <spring_stiffness>0</spring_stiffness>
          </dynamics>
          <use_parent_model_frame>1</use_parent_model_frame>
        </axis>
      </joint>
      <link name='lidar_base'>
        <pose frame=''>7.8 0.25 1.1 0 -0 0</pose>
        <inertial>
          <pose frame=''>0 0 0 0 -0 0</pose>
          <mass>1</mass>
          <inertia>
            <ixx>1</ixx>
            <ixy>0</ixy>
            <ixz>0</ixz>
            <iyy>1</iyy>
            <iyz>0</iyz>
            <izz>1</izz>
          </inertia>
        </inertial>
        <visual name='lidar_base_visual'>
          <pose frame=''>0 0 -0.125 0 -0 0</pose>
          <geometry>
            <box>
              <size>0.25 0.25 0.25</size>
            </box>
          </geometry>
          <material>
            <script>
              <name>Gazebo/Black</name>
              <uri>file://media/materials/scripts/gazebo.material</uri>
            </script>
          </material>
        </visual>
        <gravity>1</gravity>
        <velocity_decay/>
        <self_collide>0</self_collide>
        <kinematic>0</kinematic>
      </link>
      <joint name='lidar_base_joint' type='revolute'>
        <child>lidar_base</child>
        <parent>prlink3</parent>
        <axis>
          <xyz>0 1 0</xyz>
          <limit>
            <lower>-1e+16</lower>
            <upper>1e+16</upper>
          </limit>
          <dynamics>
            <damping>0.5</damping>
            <friction>0</friction>
            <spring_reference>0</spring_reference>
            <spring_stiffness>0</spring_stiffness>
          </dynamics>
          <use_parent_model_frame>1</use_parent_model_frame>
        </axis>
      </joint>
      <link name='lidar_mount'>
        <pose frame=''>7.8 0.25 0.65 0 -0 0</pose>
        <inertial>
          <pose frame=''>0 0 0 0 -0 0</pose>
          <mass>0.001</mass>
          <inertia>
            <ixx>1</ixx>
            <ixy>0</ixy>
            <ixz>0</ixz>
            <iyy>1</iyy>
            <iyz>0</iyz>
            <izz>1</izz>
          </inertia>
        </inertial>
        <visual name='lidar_mount_visual'>
          <pose frame=''>0 0 0 0 -0 0</pose>
          <geometry>
            <box>
              <size>0.04 0.1 0.4</size>
            </box>
          </geometry>
          <material>
            <script>
              <name>Gazebo/Black</name>
              <uri>file://media/materials/scripts/gazebo.material</uri>
            </script>
          </material>
        </visual>
        <gravity>1</gravity>
        <velocity_decay/>
        <self_collide>0</self_collide>
        <kinematic>0</kinematic>
      </link>
      <joint name='lidar_joint' type='revolute'>
        <child>lidar_mount</child>
        <parent>lidar_base</parent>
        <axis>
          <xyz>0 0 1</xyz>
          <limit>
            <lower>-1e+16</lower>
            <upper>1e+16</upper>
          </limit>
          <dynamics>
            <spring_reference>0</spring_reference>
            <spring_stiffness>0</spring_stiffness>
          </dynamics>
          <use_parent_model_frame>1</use_parent_model_frame>
        </axis>
      </joint>
      <static>0</static>
      <plugin name='gazebo_ros_control' filename='libgazebo_ros_control.so'>
        <robotNamespace>/cranebot</robotNamespace>
        <robotSimType>gazebo_ros_control/DefaultRobotHWSim</robotSimType>
        <legacyModeNS>true</legacyModeNS>
      </plugin>
      <pose frame=''>0 0 0 0 -0 0</pose>
    </model>
    <state world_name='default'>
      <sim_time>40 586000000</sim_time>
      <real_time>40 834144108</real_time>
      <wall_time>1600006196 659572810</wall_time>
      <iterations>40586</iterations>
      <model name='cranebot'>
        <pose frame=''>-3e-06 0 0 0 1e-06 0</pose>
        <scale>1 1 1</scale>
        <link name='lidar_base'>
          <pose frame=''>7.35474 0.255739 6.97655 1e-06 -0.307046 0.00043</pose>
          <velocity>7e-06 -0.000782 -8e-06 6e-05 0.002756 -0.000127</velocity>
          <acceleration>0.014383 -1.56355 -0.016129 0.121495 3.2e-05 -0.253751</acceleration>
          <wrench>0.014383 -1.56355 -0.016129 0 -0 0</wrench>
        </link>
        <link name='lidar_mount'>
          <pose frame=''>7.49075 0.255798 6.54759 -0.012662 -0.306793 0.042336</pose>
          <velocity>-0.001174 -0.000788 -0.000383 -0.004826 0.002754 0.015268</velocity>
          <acceleration>0.015159 -1.57431 -0.016566 -2.75417 -0.003922 -2.80951</acceleration>
          <wrench>1.5e-05 -0.001574 -1.7e-05 0 -0 0</wrench>
        </link>
        <link name='link1'>
          <pose frame=''>-3e-06 0 0 0 1e-06 0</pose>
          <velocity>0 1.7e-05 0 1.1e-05 0 0.000275</velocity>
          <acceleration>0.000604 0.023535 -7.3e-05 0.022205 0.533562 0.015831</acceleration>
          <wrench>0.000604 0.023535 -7.3e-05 0 -0 0</wrench>
        </link>
        <link name='link2'>
          <pose frame=''>-6 0 0.999986 0 -4e-06 0.00043</pose>
          <velocity>1e-06 -0.001043 2e-06 -1.4e-05 1e-06 0.000142</velocity>
          <acceleration>0.00157 -2.08357 0.004785 -0.027161 0.00123 0.284387</acceleration>
          <wrench>0.000157 -0.208357 0.000478 0 -0 0</wrench>
        </link>
        <link name='link4'>
          <pose frame=''>9.82615 0.006797 8.0639 1e-06 -8e-06 0.00043</pose>
          <velocity>-3.7e-05 -0.002379 2.6e-05 5.7e-05 -0 -0.000152</velocity>
          <acceleration>-0.07434 -4.75706 0.058007 0.114015 -0.004221 -0.304595</acceleration>
          <wrench>-7.4e-05 -0.004757 5.8e-05 0 -0 0</wrench>
        </link>
        <link name='load'>
          <pose frame=''>9.82617 0.0068 5.55234 1e-06 -8e-06 0.00043</pose>
          <velocity>-2.2e-05 -0.00196 0.00752 5.8e-05 -0 -0.00015</velocity>
          <acceleration>-0.032161 -3.92028 0.025123 0.11636 -0.00422 -0.299204</acceleration>
          <wrench>-0.003216 -0.392028 0.002512 0 -0 0</wrench>
        </link>
        <link name='prlink1'>
          <pose frame=''>-6.00002 -1e-06 1.09999 0 -0.414529 0.00043</pose>
          <velocity>2e-06 -0.001053 2e-06 -2.6e-05 -1e-06 0.000142</velocity>
          <acceleration>-0.000165 -0.135305 0.01215 -0.05261 -0.001328 0.284279</acceleration>
          <wrench>-0.000165 -0.135305 0.01215 0 -0 0</wrench>
        </link>
        <link name='prlink2'>
          <pose frame=''>-5.52337 0.000204 1.30971 -0 -0.414531 0.00043</pose>
          <velocity>-3e-06 -0.000481 8e-06 -6e-06 -0 6.7e-05</velocity>
          <acceleration>-0.00432 -0.063168 0.00987 -0.012423 0.000923 0.134868</acceleration>
          <wrench>-0.00432 -0.063168 0.00987 0 -0 0</wrench>
        </link>
        <link name='prlink3'>
          <pose frame=''>-5.27635 0.000311 1.41839 0 -0.414534 0.00043</pose>
          <velocity>-9e-06 8.3e-05 1.4e-05 1.6e-05 2e-06 -1.1e-05</velocity>
          <acceleration>-0.00759 -0.06688 0.007528 0.03188 0.003321 -0.022209</acceleration>
          <wrench>-0.00759 -0.06688 0.007528 0 -0 0</wrench>
        </link>
      </model>
      <model name='ground_plane'>
        <pose frame=''>0 0 0 0 -0 0</pose>
        <scale>1 1 1</scale>
        <link name='link'>
          <pose frame=''>0 0 0 0 -0 0</pose>
          <velocity>0 0 0 0 -0 0</velocity>
          <acceleration>0 0 0 0 -0 0</acceleration>
          <wrench>0 0 0 0 -0 0</wrench>
        </link>
      </model>
      <light name='sun'>
        <pose frame=''>0 0 10 0 -0 0</pose>
      </light>
    </state>
  </world>
</sdf>
